Workbook

Sheet journal_to_ledger
A1: OLD | E1: NEW
A2: year | B2: type | C2: cr_ledger | D2: dr_ledger | E2: type | F2: cr_ledger | G2: dr_ledger | H2: description
A3: 2021 | B3: core讲师工资 | C3: 银行存款1002 | D3: core讲师工资5501 | E3: 支出OL讲师 | F3: 银行存款 | G3: 支出OL讲师
A4: 2023 | B4: OL-奖学金 | C4: 銀行存款1002 | D4: OL收入4301 | E4: T-收入OL | F4: 银行存款 | G4: 收入OL
A5: 2024 | B5: OL-奖学金 | C5: 应付OL奖助2302 | D5: 銀行存款1002 | E5: 应付OL奖助 | F5: 应付OL奖助 | G5: 银行存款 | M5: OL讲师工资 | N5: 银行存款1002 | O5: OL讲师/组委工资
A6: 2023 | B6: OL-讲师 | C6: 銀行存款1002 | D6: OL讲师工资5401 | E6: 支出OL讲师 | F6: 银行存款 | G6: 支出OL讲师 | M6: 书院讲师工资 | N6: 银行存款1002 | O6: 工作坊/书院讲师工资
A7: 2021 | B7: OL-讲师 | C7: 银行存款1002 | D7: OL讲师工资5401 | E7: 支出OL讲师 | F7: 银行存款 | G7: 支出OL讲师 | M7: 书院组委工资 | N7: 银行存款1002 | O7: 工作坊/书院组委工资
A8: 2024 | B8: OL-讲师工资 | C8: 銀行存款1002 | D8: OL讲师工资5401 | E8: 支出OL讲师 | F8: 银行存款 | G8: 支出OL讲师 | M8: 书院-FEE | N8: 银行存款1002 | O8: 工作坊/书院活动成本5101
A9: 2023 | B9: 研讨屋 | C9: 銀行存款1002 | D9: 业务活动成本5001 | E9: 支出内容运营 | F9: 银行存款 | G9: 支出内容运营 | M9: 书院讲师报销 | N9: 银行存款1002 | O9: 工作坊/书院活动成本5101
A10: 2024 | B10: 聚餐 | C10: 銀行存款1002 | D10: 业务活动成本5001 | E10: 社群维护 | F10: 银行存款 | G10: 社群维护 | M10: Workshop讲师工资 | N10: 银行存款1002 | O10: 工作坊/书院讲师工资
A11: 2022 | B11: 运营报销 | C11: 銀行存款1002 | D11: 业务活动成本5001 | E11: 支出内容运营 | F11: 银行存款 | G11: 支出内容运营
A12: 2022 | B12: 通讯 | C12: 銀行存款1002 | D12: 业务活动成本5001 | E12: 支出内容运营 | F12: 银行存款 | G12: 支出内容运营 | M12: Worshop组委工资 | N12: 银行存款1002 | O12: 工作坊/书院组委工资
A13: 2020 | B13: Veitgeist | C13: 银行存款1002 | D13: 业务活动成本5101 | E13: 支出内容运营 | F13: 银行存款 | G13: 支出内容运营 | M13: Workshop-FEE | N13: 银行存款1002 | O13: 工作坊/书院活动成本5101
A14: 2020 | B14: wage | C14: 银行存款1002 | D14: 业务活动成本5101 | E14: 组委工资 | F14: 银行存款 | G14: 组委工资 | M14: 研讨屋 | N14: 银行存款1002 | O14: 工作坊/书院活动成本5101
A15: 2020 | B15: Workshop-WAGE | C15: 银行存款1002 | D15: 业务活动成本5101 | E15: 支出SC组委 | F15: 银行存款 | G15: 支出SC组委 | M15: OL押金 | N15: 其他应付款 | O15: 银行存款
A16: 2020 | B16: 报销 | C16: 银行存款1002 | D16: 业务活动成本5101 | E16: 支出SC运营 | F16: 银行存款 | G16: 支出SC运营 | M16: OL押金 | N16: 银行存款 | O16: 其他应付款
A17: 2020 | B17: 讲师 | C17: 银行存款1002 | D17: 业务活动成本5101 | E17: 支出OL讲师 | F17: 银行存款 | G17: 支出OL讲师 | M17: OL退费 | N17: 银行存款1002 | O17: 提供服务收入4301
A18: 2024 | B18: 书院住宿 | C18: 銀行存款1002 | D18: 书院讲师组委工资5301 | E18: 支出SC运营 | F18: 银行存款 | G18: 支出SC运营 | M18: Workshop退费 | N18: 银行存款1002 | O18: 提供服务收入4301
A19: 2024 | B19: 书院工资 | C19: 銀行存款1002 | D19: 书院讲师组委工资5301 | E19: 支出SC讲师 | F19: 银行存款 | G19: 支出SC讲师 | M19: 书院退费 | N19: 银行存款1002 | O19: 提供服务收入4301
A20: 2024 | B20: 书院报销 | C20: 銀行存款1002 | D20: 书院运营成本5101 | E20: 支出SC运营 | F20: 银行存款 | G20: 支出SC运营 | M20: 书院优惠 | N20: 其他应付款 | O20: 银行存款
A21: 2024 | B21: 书院场地 | C21: 銀行存款1002 | D21: 书院运营成本5101 | E21: 支出SC运营 | F21: 银行存款 | G21: 支出SC运营
A22: 2024 | B22: 书院运营 | C22: 銀行存款1002 | D22: 书院运营成本5101 | E22: 支出SC运营 | F22: 银行存款 | G22: 支出SC运营 | M22: 网站 | N22: 银行存款1002 | O22: 管理费用5201
A23: 2020 | B23: OL-D | C23: 银行存款1002 | D23: 其他应付款2209 | E23: T-应付OL押金 | F23: 银行存款 | G23: 应付OL押金 | M23: 服务费 | N23: 银行存款1002 | O23: 管理费用5201
A24: 2021 | B24: OL-D | C24: 银行存款1002 | D24: 其他应付款2209 | E24: T-应付OL押金 | F24: 银行存款 | G24: 应付OL押金 | M24: Promo | N24: 银行存款1002 | O24: 管理费用5201
A25: 2022 | B25: OL-D | C25: 銀行存款1002 | D25: 其他應付款(押金)2209 | E25: 应付OL押金 | F25: 银行存款 | G25: 应付OL押金
A26: 2023 | B26: OL-D | C26: 銀行存款1002 | D26: 其他應付款(押金)2209 | E26: 应付OL押金 | F26: 银行存款 | G26: 应付OL押金 | M26: 退税 | N26: 应交税金2206 | O26: 银行存款1002
A27: 2024 | B27: OL-D | C27: 銀行存款1002 | D27: 其他應付款(押金)2209 | E27: 应付OL押金 | F27: 银行存款 | G27: 应付OL押金 | M27: 权益变动 | N27: 非限定性净资产3101 | O27: 银行存款1002
A28: 2023 | B28: OL-D&OL助学金 | C28: 銀行存款1002 | D28: 其他應付款(押金)2209 | E28: 应付OL押金 | F28: 银行存款 | G28: 应付OL押金 | M28: 转账 | N28: 银行存款1002 | O28: 银行存款1002
A29: 2024 | B29: 换汇-3000刀 | C29: 銀行存款1002 | D29: 其他貨幣資金1009 | E29: 银行存款 | F29: 银行存款 | G29: 其他货币资金
A30: 2023 | B30: 书院-助学金 | C30: 銀行存款1002 | D30: 工作坊/书院收入4201 | E30: 应付SC奖助 | F30: 银行存款 | G30: 应付SC奖助
A31: 2021 | B31: workshop-工资 | C31: 银行存款1002 | D31: 工作坊讲师工资5301 | E31: 支出SC讲师 | F31: 银行存款 | G31: 支出SC讲师
A32: 2023 | B32: 书院-组委讲师 | C32: 銀行存款1002 | D32: 工作坊讲师工资5301 | E32: 支出SC组委 | F32: 银行存款 | G32: 支出SC组委
A33: 2023 | B33: 书院-讲师组委 | C33: 銀行存款1002 | D33: 工作坊讲师工资5301 | E33: 支出SC讲师 | F33: 银行存款 | G33: 支出SC讲师
A34: 2023 | B34: 书院-运营 | C34: 銀行存款1002 | D34: 工作坊讲师工资5301 | E34: 支出SC运营 | F34: 银行存款 | G34: 支出SC运营
A35: 2023 | B35: 书院-酒店 | C35: 銀行存款1002 | D35: 工作坊讲师工资5301 | E35: 支出SC运营 | F35: 银行存款 | G35: 支出SC运营
A36: 2023 | B36: ? | C36: 銀行存款1002 | D36: 工作坊运营成本5101 | E36: 支出SC运营 | F36: 银行存款 | G36: 支出SC运营
A37: 2023 | B37: 书院-物料 | C37: 銀行存款1002 | D37: 工作坊运营成本5101 | E37: 支出SC运营 | F37: 银行存款 | G37: 支出SC运营
A38: 2020 | B38: 缴税 | C38: 银行存款1002 | D38: 所得税费用5402 | E38: 所得税税款 | F38: 银行存款 | G38: 所得税税款
A39: 2020 | B39: OL-A | C39: 银行存款1002 | D39: 提供服务收入4301 | E39: T-收入OL | F39: 银行存款 | G39: 收入OL
A40: 2024 | B40: 播客 | C40: 銀行存款1002 | D40: 播客/研讨屋5501 | E40: 支出内容运营 | F40: 银行存款 | G40: 支出内容运营
...

Sheet ledger_new
A1: ledger name | B1: ledger ID | C1: #1 | E1: #2 | G1: #3 | I1: #4 | K1: 备注
A2: 银行存款 | B2: 1100 | C2: 1 | D2: 资产 | E2: 1 | F2: 人民币银行账户存款
A3: 其他货币资金 | B3: 1200 | E3: 2 | F3: 其他货币资金
A4: 短期借款 | B4: 2010 | C4: 2 | D4: 应付款 | E4: 0 | F4: 组织运营 | G4: 1 | H4: 短期借款
A5: 应付SC押金 | B5: 2201 | E5: 2 | F5: 线下活动 | G5: 0 | H5: 书院/工作坊 | I5: 1 | J5: 押金
A6: 应付SC奖助 | B6: 2202 | I6: 2 | J6: 助学金/奖学金
A7: 应付税款 | B7: 2209 | I7: 9 | J7: 应付税款 | K7: （退税）
A8: 应付OL押金 | B8: 2301 | E8: 3 | F8: 线上活动 | G8: 0 | H8: 线上课程 | I8: 1 | J8: 押金
A9: 应付OL奖助 | B9: 2302 | I9: 2 | J9: 助学金/奖学金
A10: 权益变动 | B10: 3000 | C10: 3 | D10: 权益 | E10: 0 | G10: 0
A11: 捐赠收入 | B11: 4020 | C11: 4 | D11: 收入 | E11: 0 | F11: 组织运营 | G11: 2 | H11: 捐赠收入
A12: 投资收益 | B12: 4030 | G12: 3 | H12: 投资收益
A13: 收入SC | B13: 4200 | E13: 2 | F13: 线下活动 | G13: 0 | H13: 书院/工作坊
A14: 收入OL | B14: 4300 | E14: 3 | F14: 线上活动 | G14: 0 | H14: 线上课程
A15: 管理费用 | B15: 5000 | C15: 5 | D15: 支出 | E15: 0 | F15: 组织运营 | G15: 0 | H15: 管理费用
A16: 组委工资 | B16: 5010 | G16: 1 | H16: 组委工资
A17: 宣传推广 | B17: 5020 | G17: 2 | H17: 宣传推广
A18: 社群维护 | B18: 5030 | G18: 3 | H18: 社群维护
A19: 所得税税款 | B19: 5090 | G19: 9 | H19: 所得税税款
A20: 支出SC讲师 | B20: 5201 | E20: 2 | F20: 线下活动 | G20: 0 | H20: 书院/工作坊 | I20: 1 | J20: 讲师
A21: 支出SC组委 | B21: 5202 | I21: 2 | J21: 组委
A22: 支出SC运营 | B22: 5203 | I22: 3 | J22: 运营
A23: 支出OL讲师 | B23: 5301 | E23: 3 | F23: 线上活动 | G23: 0 | H23: 线上课程 | I23: 1 | J23: 讲师
A24: 支出OL组委 | B24: 5302 | I24: 2 | J24: 组委
A25: 支出OL运营 | B25: 5303 | I25: 3 | J25: 运营
A26: 支出内容运营 | B26: 5310 | G26: 1 | H26: 播客/研讨屋/通讯

Sheet ledger_old
A1: OLD
A2: year | B2: ledger name | C2: ledger ID
A3: 2021 | B3: core讲师工资 | C3: 5501
A4: 2022 | B4: core讲师工资 | C4: 5501
A5: 2023 | B5: core讲师工资 | C5: 5501
A6: 2021 | B6: OL收入 | C6: 4301
A7: 2022 | B7: OL收入 | C7: 4301
A8: 2023 | B8: OL收入 | C8: 4301
A9: 2024 | B9: OL收入 | C9: 4301
A10: 2021 | B10: OL讲师工资 | C10: 5401
A11: 2022 | B11: OL讲师工资 | C11: 5401
A12: 2023 | B12: OL讲师工资 | C12: 5401
A13: 2024 | B13: OL讲师工资 | C13: 5401
A14: 2020 | B14: 业务活动成本 | C14: 5101
... A104: 2021 | B104: 预收账款 | C104: 2203

Sheet journal
A1: OLD | D1: NEW
A2: year | B2: 摘要 | C2: type | D2: type
A3: 2022 | B3: 余利宝-基金赎回，转账到支付宝 | C3: 余利宝 | D3: =VLOOKUP(C3,journal_to_ledger!B:E,4,FALSE)
A4: 2022 | B4: 课程押金，感谢参与～ | C4: OL-D | D4: =VLOOKUP(C4,journal_to_ledger!B:E,4,FALSE)
A5: 2022 | B5: 余利宝自动转入 | C5: 余利宝 | D5: =VLOOKUP(C5,journal_to_ledger!B:E,4,FALSE)
A6: 2022 | B6: 唯理教育简报年终幸运读者，感谢支持～ | C6: 通讯 | D6: =VLOOKUP(C6,journal_to_ledger!B:E,4,FALSE)
A7: 2022 | B7: OL30 TA | C7: 工资 | D7: =VLOOKUP(C7,journal_to_ledger!B:E,4,FALSE)
A8: 2022 | B8: OL30 运营 | C8: 工资 | D8: =VLOOKUP(C8,journal_to_ledger!B:E,4,FALSE)
A9: 2022 | B9: 12月月度简报 | C9: 工资 | D9: =VLOOKUP(C9,journal_to_ledger!B:E,4,FALSE)
A10: 2022 | B10: 公众号活动报销 | C10: 报销 | D10: =VLOOKUP(C10,journal_to_ledger!B:E,4,FALSE)
A11: 2022 | B11: 服务器报销 | C11: / | D11: =VLOOKUP(C11,journal_to_ledger!B:E,4,FALSE)
A12: 2022 | B12: 报销服务器 | C12: 报销 | D12: =VLOOKUP(C12,journal_to_ledger!B:E,4,FALSE)
A13: 2022 | B13: 线上课程TA | C13: 工资 | D13: =VLOOKUP(C13,journal_to_ledger!B:E,4,FALSE)
A14: 2022 | B14: 回顾微信推送 | C14: 工资 | D14: =VLOOKUP(C14,journal_to_ledger!B:E,4,FALSE)
... A20: 2022 | B20: OL29录像 | C20: OL-N | D20: =VLOOKUP(C20,journal_to_ledger!B:E,4,FALSE)
A21: 2022 | C21: 基金收益 | D21: =VLOOKUP(C21,journal_to_ledger!B:E,4,FALSE)
A22: 2022 | C22: 基金赎回，基金账户转出 | D22: =VLOOKUP(C22,journal_to_ledger!B:E,4,FALSE)
A23: 2022 | C23: 基金申购，转入基金账户 | D23: =VLOOKUP(C23,journal_to_ledger!B:E,4,FALSE)
A24: 2022 | B24: / | C24: 赞赏 | D24: =VLOOKUP(C24,journal_to_ledger!B:E,4,FALSE)
A25: 2022 | B25: 商务卡-单位结算卡年费 | C25: 运营 | D25: =VLOOKUP(C25,journal_to_ledger!B:E,4,FALSE)
A26: 2022 | B26: 结息 | C26: 结息 | D26: =VLOOKUP(C26,journal_to_ledger!B:E,4,FALSE)
A27: 2022 | B27: OL32 李玉青 | C27: OL | D27: =VLOOKUP(C27,journal_to_ledger!B:E,4,FALSE)
A28: 2022 | B28: OL32刘熙宁 | C28: OL | D28: =VLOOKUP(C28,journal_to_ledger!B:E,4,FALSE)
A29: 2022 | B29: OL32+陈轩 | C29: OL | D29: =VLOOKUP(C29,journal_to_ledger!B:E,4,FALSE)
A30: 2022 | B30: 转账 | C30: OL | D30: =VLOOKUP(C30,journal_to_ledger!B:E,4,FALSE)
A31: 2022 | B31: OL32 谈鹤 | C31: OL | D31: =VLOOKUP(C31,journal_to_ledger!B:E,4,FALSE)
A32: 2022 | B32: OL32朱文正 | C32: OL | D32: =VLOOKUP(C32,journal_to_ledger!B:E,4,FALSE)
A33: 2022 | B33: OL32 向翌晨 | C33: OL | D33: =VLOOKUP(C33,journal_to_ledger!B:E,4,FALSE)
A34: 2022 | B34: OL32+范荣庆 押金 | C34: OL | D34: =VLOOKUP(C34,journal_to_ledger!B:E,4,FALSE)
A35: 2022 | B35: OL32+范荣庆 学费 | C35: OL | D35: =VLOOKUP(C35,journal_to_ledger!B:E,4,FALSE)
... A167: 2022 | B167: 企业网银高级版 | C167: 运营 | D167: =VLOOKUP(C167,journal_to_ledger!B:E,4,FALSE)
A168: 2022 | C168: 结息 | D168: =VLOOKUP(C168,journal_to_ledger!B:E,4,FALSE)
A169: 2022 | B169: 武外英中张笑晗唯理线上书院缴费 | C169: 书院 | D169: =VLOOKUP(C169,journal_to_ledger!B:E,4,FALSE)
A170: 2022 | B170: 陈依唯，广东碧桂园学校 | C170: 书院 | D170: =VLOOKUP(C170,journal_to_ledger!B:E,4,FALSE)
A171: 2022 | B171: 南京大学徐静 | C171: 书院 | D171: =VLOOKUP(C171,journal_to_ledger!B:E,4,FALSE)
A172: 2022 | B172: 董泠君广州华附国际部HFI | C172: 书院 | D172: =VLOOKUP(C172,journal_to_ledger!B:E,4,FALSE)
A173: 2022 | B173: 赵姗姗深圳国际交流学院 | C173: 书院 | D173: =VLOOKUP(C173,journal_to_ledger!B:E,4,FALSE)
A174: 2022 | B174: 王柯颖，济南外国语学校 | C174: 书院 | D174: =VLOOKUP(C174,journal_to_ledger!B:E,4,FALSE)
A175: 2022 | B175: 备注是赵一伟SantaMonicaCollege | C175: 书院 | D175: =VLOOKUP(C175,journal_to_ledger!B:E,4,FALSE)
A176: 2022 | B176: 侯靖淇北师大实验中学 | C176: 书院 | D176: =VLOOKUP(C176,journal_to_ledger!B:E,4,FALSE)
...
